Workbook

Sheet 🏠 Accueil
B2: COCKPIT CRITÈRE 7 — AMÉLIORATION CONTINUE
B3: Classeur unique navigable — Ind. 30 (appréciations) · Ind. 31 (réclamations) · Ind. 32 (amélioration)
B6: NAVIGATION
B7: ❓ Questionnaires (réf.) | D7: 🔥 Saisie Bénéficiaire
B8: 🎓 Saisie Formateur/Équipe | D8: 🤝 Saisie Entreprise/Financeur
B9: 📊 Synthèse Satisfaction | D9: 📋 Registre Réclamations
B10: 📈 Plan d'Amélioration (PAQ) | D10: 🔄 Revues qualité
B12: 🎯 TABLEAU DE BORD GLOBAL CRITÈRE 7
B13: Indicateur | E13: Valeur
B14: Ind. 30 — Note globale satisfaction (/5) | E14: ='📊 Synthèse Satisf'!C11 -> 0
B15: Ind. 30 — Taux de recommandation | E15: ='📊 Synthèse Satisf'!C12 -> 0
B16: Ind. 31 — Réclamations clôturées / total | E16: =IFERROR('📋 Réclamations'!H35/'📋 Réclamations'!F35,0) -> 0
B17: Ind. 31 — Réclamations en retard (alerte) | E17: ='📋 Réclamations'!J35 -> 0
B18: Ind. 32 — Taux de réalisation du PAQ | E18: =IFERROR('📈 PAQ'!H41/'📈 PAQ'!F41,0) -> 0
B19: Ind. 32 — Actions PAQ en retard (alerte) | E19: ='📈 PAQ'!J41 -> 0
B21: 💡 Comment utiliser ce cockpit | C21: 1) Onglet « Questionnaires réf » = les 3 trames à diffuser. 2) Saisir les retours dans les 3 onglets de saisie (Bénéficiaire / Formateur / Entreprise). 3) Les moyennes par item se calculent seules. 4) Réclamations + PAQ tracés dans leurs onglets. 5) Ce tableau de bord se met à jour automatiquement. Cliquez sur les boutons orange pour naviguer.

Sheet ❓ Questionnaires réf
B1: ← Retour à l'accueil
B2: ❓ QUESTIONNAIRES — RÉFÉRENTIEL
B3: Les 3 trames à diffuser — échelle 1 (Très insatisfait) à 5 (Très satisfait)
B6: 1 · QUESTIONNAIRE BÉNÉFICIAIRE (à chaud + à froid)
B7: # | C7: Question | D7: Type
B8: 1 | C8: Les objectifs annoncés ont-ils été atteints ? | D8: Note 1-5
B9: 2 | C9: Le contenu correspond-il à vos attentes initiales ? | D9: Note 1-5
B10: 3 | C10: Qualité de l'animation et de l'expertise du formateur | D10: Note 1-5
B11: 4 | C11: Clarté des explications et des supports | D11: Note 1-5
B12: 5 | C12: Rythme et équilibre théorie / pratique | D12: Note 1-5
B13: 6 | C13: Qualité de l'accueil et de l'information avant la formation | D13: Note 1-5
B14: 7 | C14: Conditions matérielles (salle / plateforme) | D14: Note 1-5
B15: 8 | C15: Respect des horaires et du programme | D15: Note 1-5
B16: 9 | C16: [À FROID N+3/N+6] Avez-vous mis en pratique les acquis ? (note d'impact) | D16: Note 1-5
B17: 10 | C17: [À FROID] Avec le recul, la formation a-t-elle répondu à vos besoins ? | D17: Note 1-5
B18: 11 | C18: Points forts de la formation ? (ouverte) | D18: Ouverte
B19: 12 | C19: Aspects à améliorer ? (ouverte) | D19: Ouverte
... B21: 14 | C21: [À FROID] Effets concrets identifiés (poste, missions, compétences) ? | D21: Ouverte
B23: 2 · QUESTIONNAIRE FORMATEUR / ÉQUIPE PÉDAGOGIQUE
B24: # | C24: Question | D24: Type
B25: 1 | C25: Clarté des objectifs et du cahier des charges transmis | D25: Note 1-5
B26: 2 | C26: Adéquation du programme au public réel | D26: Note 1-5
B27: 3 | C27: Qualité des supports et ressources mis à disposition | D27: Note 1-5
B28: 4 | C28: Conditions matérielles / techniques d'intervention | D28: Note 1-5
B29: 5 | C29: Qualité de la coordination pédagogique (briefing, échanges) | D29: Note 1-5
B30: 6 | C30: Niveau de préparation des bénéficiaires (positionnement) | D30: Note 1-5
B31: 7 | C31: Soutien de l'organisme en cas de difficulté | D31: Note 1-5
B32: 8 | C32: Satisfaction globale de la collaboration | D32: Note 1-5
B33: 9 | C33: Points forts de l'organisation pédagogique ? (ouverte) | D33: Ouverte
B34: 10 | C34: Difficultés rencontrées / axes d'amélioration ? (ouverte) | D34: Ouverte
B35: 11 | C35: Suggestions pour améliorer la prestation ? (ouverte) | D35: Ouverte
B37: 3 · QUESTIONNAIRE ENTREPRISE / FINANCEUR
B38: # | C38: Question | D38: Type
B39: 1 | C39: La prestation a-t-elle répondu au besoin exprimé ? | D39: Note 1-5
B40: 2 | C40: Qualité de la relation et de la communication | D40: Note 1-5
B41: 3 | C41: Effets observés sur le(s) collaborateur(s) formé(s) | D41: Note 1-5
B42: 4 | C42: Qualité administrative (conventions, facturation, reporting) | D42: Note 1-5
B43: 5 | C43: Respect des engagements (délais, contenu, modalités) | D43: Note 1-5
B44: 6 | C44: [CFA] Progression de l'apprenti / qualité lien CFA-entreprise | D44: Note 1-5
B45: 7 | C45: Points forts de la collaboration ? (ouverte) | D45: Ouverte
...

Sheet 🔥 Saisie Bénéficiaire
B1: ← Retour à l'accueil
B2: 🔥 SAISIE — QUESTIONNAIRE BÉNÉFICIAIRE (chaud + froid)
B3: Une ligne par retour. Colonne « Moment » = Chaud ou Froid. Notes 1 à 5.
B6: N° | C6: Date | D6: Action / Session | E6: Moment (C/F) | F6: Reco (O/N) | G6: Q1 | H6: Q2 | I6: Q3 | J6: Q4 | K6: Q5 | L6: Q6 | M6: Q7 | N6: Q8 | O6: Q9 | P6: Q10 | Q6: Verbatim clé
B7: Légende → | G7: Q1 | H7: Q2 | I7: Q3 | J7: Q4 | K7: Q5 | L7: Q6 | M7: Q7 | N7: Q8 | O7: Q9 | P7: Q10 | Q7: (survol Qn = texte)
B48: MOYENNE | G48: =IFERROR(AVERAGE(G8:G47),0) -> 0 | H48: =IFERROR(AVERAGE(H8:H47),0) -> 0 | I48: =IFERROR(AVERAGE(I8:I47),0) -> 0 | J48: =IFERROR(AVERAGE(J8:J47),0) -> 0 | K48: =IFERROR(AVERAGE(K8:K47),0) -> 0 | L48: =IFERROR(AVERAGE(L8:L47),0) -> 0 | M48: =IFERROR(AVERAGE(M8:M47),0) -> 0 | N48: =IFERROR(AVERAGE(N8:N47),0) -> 0 | ... P48: =IFERROR(AVERAGE(P8:P47),0) -> 0
B49: NOTE GLOBALE (moyenne des items) | G49: =IFERROR(AVERAGE(G48:P48),0) -> 0

Sheet 🎓 Saisie Formateur
B1: ← Retour à l'accueil
B2: 🎓 SAISIE — QUESTIONNAIRE FORMATEUR / ÉQUIPE PÉDAGOGIQUE
B3: Une ligne par retour formateur/intervenant. Notes 1 à 5.
B6: N° | C6: Date | D6: Action / Session | E6: Q1 | F6: Q2 | G6: Q3 | H6: Q4 | I6: Q5 | J6: Q6 | K6: Q7 | L6: Q8 | M6: Verbatim clé
B7: Légende → | E7: Q1 | F7: Q2 | G7: Q3 | H7: Q4 | I7: Q5 | J7: Q6 | K7: Q7 | L7: Q8 | M7: (survol Qn = texte)
B33: MOYENNE | E33: =IFERROR(AVERAGE(E8:E32),0) -> 0 | F33: =IFERROR(AVERAGE(F8:F32),0) -> 0 | G33: =IFERROR(AVERAGE(G8:G32),0) -> 0 | H33: =IFERROR(AVERAGE(H8:H32),0) -> 0 | I33: =IFERROR(AVERAGE(I8:I32),0) -> 0 | J33: =IFERROR(AVERAGE(J8:J32),0) -> 0 | K33: =IFERROR(AVERAGE(K8:K32),0) -> 0 | L33: =IFERROR(AVERAGE(L8:L32),0) -> 0
B34: NOTE GLOBALE (moyenne des items) | E34: =IFERROR(AVERAGE(E33:L33),0) -> 0

Sheet 🤝 Saisie Entreprise
B1: ← Retour à l'accueil
B2: 🤝 SAISIE — QUESTIONNAIRE ENTREPRISE / FINANCEUR
B3: Une ligne par retour entreprise/financeur/maître d'apprentissage. Notes 1 à 5.
B6: N° | C6: Date | D6: Action / Session | E6: Type (E/F/MA) | F6: Reco (O/N) | G6: Q1 | H6: Q2 | I6: Q3 | J6: Q4 | K6: Q5 | L6: Q6 | M6: Verbatim clé
B7: Légende → | G7: Q1 | H7: Q2 | I7: Q3 | J7: Q4 | K7: Q5 | L7: Q6 | M7: (survol Qn = texte)
B28: MOYENNE | G28: =IFERROR(AVERAGE(G8:G27),0) -> 0 | H28: =IFERROR(AVERAGE(H8:H27),0) -> 0 | I28: =IFERROR(AVERAGE(I8:I27),0) -> 0 | J28: =IFERROR(AVERAGE(J8:J27),0) -> 0 | K28: =IFERROR(AVERAGE(K8:K27),0) -> 0 | L28: =IFERROR(AVERAGE(L8:L27),0) -> 0
B29: NOTE GLOBALE (moyenne des items) | G29: =IFERROR(AVERAGE(G28:L28),0) -> 0

Sheet 📊 Synthèse Satisf
B1: ← Retour à l'accueil
B2: 📊 SYNTHÈSE SATISFACTION
B3: Consolidation des 3 questionnaires — Ind. 30
B6: INDICATEUR | C6: Note /5 | D6: Nb retours
B7: Bénéficiaires (chaud + froid) | C7: ='🔥 Saisie Bénéficiaire'!G49 -> 0 | D7: =COUNTA('🔥 Saisie Bénéficiaire'!D8:D47) -> 0
B8: Formateurs / équipe pédagogique | C8: ='🎓 Saisie Formateur'!E34 -> 0 | D8: =COUNTA('🎓 Saisie Formateur'!D8:D32) -> 0
B9: Entreprises / financeurs | C9: ='🤝 Saisie Entreprise'!G29 -> 0 | D9: =COUNTA('🤝 Saisie Entreprise'!D8:D27) -> 0
B11: NOTE GLOBALE SATISFACTION (Ind. 30) | C11: =IFERROR(AVERAGE('🔥 Saisie Bénéficiaire'!G49,'🎓 Saisie Formateur'!E34,'🤝 Saisie Entreprise'!G29),0) -> 0
B12: Taux de recommandation (bénéficiaires) | C12: =IFERROR(COUNTIF('🔥 Saisie Bénéficiaire'!F8:F47,"O")/COUNTA('🔥 Saisie Bénéficiaire'!F8:F47),0) -> 0
B14: ANALYSE & ACTIONS (→ PAQ)
B15: Points forts récurrents | C15: [ Ex. expertise formateurs, cas pratiques ]
B16: Points faibles récurrents | C16: [ Ex. rythme fin de journée ]
B17: Écart chaud / froid (impact réel) | C17: [ Ex. satisfaction maintenue à froid ]
B18: Actions décidées → PAQ | C18: [ Réf. action inscrite onglet PAQ ]

Sheet 📋 Réclamations
B1: ← Retour à l'accueil
B2: 📋 REGISTRE DES RÉCLAMATIONS (Ind. 31)
B3: Une ligne par réclamation — du dépôt à la clôture
B6: N° | C6: Date reçue | D6: Origine | E6: Type | F6: Objet | G6: Gravité | H6: Accusé 48h | I6: Date réponse | J6: Action corrective | K6: Statut
B7: R01 | C7: 12/02/26 | D7: Bénéficiaire | E7: Pédagogique | F7: Rythme trop rapide module 3 | G7: Modéré | H7: Oui | I7: 20/02/26 | J7: Séquençage révisé S+1 | K7: Clôturée
B8: R02 | C8: 05/03/26 | D8: Entreprise | E8: Organisationnel | F8: Reporting en retard | G8: Mineur | H8: Oui | I8: 07/03/26 | J8: Reporting automatisé | K8: Clôturée
B35: BILAN | E35: Total : | F35: =COUNTA(F9:F33) -> 0 | G35: Clôturées : | H35: =COUNTIF(K9:K33,"Clôturée") -> 0 | I35: En retard : | J35: =COUNTIF(K9:K33,"En retard") -> 0

Sheet 📈 PAQ
B1: ← Retour à l'accueil
B2: 📈 PLAN D'AMÉLIORATION QUALITÉ (Ind. 32)
B3: 1 ligne = 1 action. Source → action → responsable → délai → statut
B6: N° | C6: Détectée le | D6: Source | E6: Problème / Opportunité | F6: Action décidée | G6: Responsable | H6: Échéance | I6: Priorité | J6: Statut
B7: A01 | C7: 30/01/26 | D7: Satisf. Bénéf. | E7: Rythme dense fin de J2 | F7: Refonte séquençage module 3 | G7: Resp. péda | H7: 28/02/26 | I7: Moyenne | J7: Terminée
B8: A02 | C8: 05/03/26 | D8: Réclamation | E8: Reporting financeur en retard | F8: Automatisation reporting | G8: Direction | H8: 30/04/26 | I8: Haute | J8: Terminée
B9: A03 | C9: 12/03/26 | D9: Veille | E9: Réforme CPF | F9: Révision contrats + fiches web | G9: Réf. qualité | H9: 31/03/26 | I9: Haute | J9: Terminée
B41: BILAN | E41: Total : | F41: =COUNTA(F10:F39) -> 0 | G41: Terminées : | H41: =COUNTIF(J10:J39,"Terminée") -> 0 | I41: Retard : | J41: =COUNTIF(J10:J39,"En retard") -> 0

Sheet 🔄 Revues qualité
B1: ← Retour à l'accueil
B2: 🔄 REGISTRE DES REVUES QUALITÉ (Ind. 32)
B3: Revues de direction / réunions qualité / conseil de perfectionnement CFA
B6: N° | C6: Date | D6: Type | E6: Participants | F6: Décisions / Points clés | G6: CR réf.
B7: 01 | C7: 15/01/26 | D7: Revue de direction | E7: Direction + Réf. qualité + Resp. péda | F7: Bilan 2025, objectifs 2026, validation PAQ | G7: RDD-2026-01
B8: 02 | C8: 20/05/26 | D8: Conseil perfectionnement | E8: Voir composition (CFA) | F8: Taux insertion, réclamations, plan N+1 | G8: PV-CP-2026-01
